Workbook

Sheet S1
A1: ='[1]Khandelwal Driver'!$C$5&" "&'[1]Khandelwal Driver'!$C$6 -> Balai Svyam Seva Sasthan Surpura
A2: =[2]S1!A2 -> 44817 | D2: LIST | J2: Khandelwal Software
A3: A/c no. | B3: Name | C3: Nest Lo. | D3: Discount | E3: Kist | F3: K.P. | G3: Loan | H3: L.P. | I3: Inter | J3: Other | K3: Total | L3: L.Balance | M3: Loan T | N3: phone
A4: 0
A5: 3052 | B5: =[3]Name!E2056 -> Ramesvar Prasad Sachoriya | C5: =[2]S1!C6 -> 1500 | D5: =[2]S1!D6 -> 0 | E5: =[2]S1!E6 -> 0 | F5: =[2]S1!F6 -> 0 | G5: =[2]S1!G6 -> 0 | H5: =[2]S1!H6 -> 0 | I5: =[2]S1!I6 -> 80 | J5: =[2]S1!J6 -> 0 | ... M5: =[2]S1!M6 -> 10 | N5: =[2]S1!P6 -> 9928577989
A6: 3053 | B6: =[3]Name!E2057 -> Santosh Devi Sachoriya | C6: =[2]S1!C7 -> 2000 | D6: =[2]S1!D7 -> 0 | E6: =[2]S1!E7 -> 0 | F6: =[2]S1!F7 -> 0 | G6: =[2]S1!G7 -> 2000 | H6: =[2]S1!H7 -> 0 | I6: =[2]S1!I7 -> 220 | J6: =[2]S1!J7 -> 0 | ... M6: =[2]S1!M7 -> 10 | N6: =[2]S1!P7 -> 9928577989
A7: 3054 | B7: =[3]Name!E2058 -> Bansi Lal | C7: =[2]S1!C8 -> 0 | D7: =[2]S1!D8 -> 0 | E7: =[2]S1!E8 -> 200 | F7: =[2]S1!F8 -> 0 | G7: =[2]S1!G8 -> 0 | H7: =[2]S1!H8 -> 0 | I7: =[2]S1!I8 -> 150 | J7: =[2]S1!J8 -> 0 | ... M7: =[2]S1!M8 -> 1 | N7: =[2]S1!P8 -> 9680409946
A8: 3055 | B8: =[3]Name!E2059 -> Manphuli Devi | C8: =[2]S1!C9 -> 18900 | D8: =[2]S1!D9 -> 0 | E8: =[2]S1!E9 -> 200 | F8: =[2]S1!F9 -> 0 | G8: =[2]S1!G9 -> 2091 | H8: =[2]S1!H9 -> 0 | I8: =[2]S1!I9 -> 200 | J8: =[2]S1!J9 -> 0 | ... M8: =[2]S1!M9 -> 5 | N8: =[2]S1!P9 -> 9680409946
A9: 3056 | B9: =[3]Name!E2060 -> Dindayal Balai | C9: =[2]S1!C10 -> 0 | D9: =[2]S1!D10 -> 0 | E9: =[2]S1!E10 -> 200 | F9: =[2]S1!F10 -> 0 | G9: =[2]S1!G10 -> 0 | H9: =[2]S1!H10 -> 0 | I9: =[2]S1!I10 -> 191 | J9: =[2]S1!J10 -> 0 | ... M9: =[2]S1!M10 -> 2 | N9: =[2]S1!P10 -> 7742016348
A10: 3057 | B10: =[3]Name!E2061 -> Mohit Balai | C10: =[2]S1!C11 -> 0 | D10: =[2]S1!D11 -> 0 | E10: =[2]S1!E11 -> 200 | F10: =[2]S1!F11 -> 0 | G10: =[2]S1!G11 -> 0 | H10: =[2]S1!H11 -> 0 | I10: =[2]S1!I11 -> 200 | J10: =[2]S1!J11 -> 0 | ... M10: =[2]S1!M11 -> 2 | N10: =[2]S1!P11 -> 7742016348
A11: 3058 | B11: =[3]Name!E2062 -> Divyansi Kimari Depan | C11: =[2]S1!C12 -> 1500 | D11: =[2]S1!D12 -> 0 | E11: =[2]S1!E12 -> 0 | F11: =[2]S1!F12 -> 0 | G11: =[2]S1!G12 -> 1500 | H11: =[2]S1!H12 -> 0 | I11: =[2]S1!I12 -> 240 | J11: =[2]S1!J12 -> 0 | ... M11: =[2]S1!M12 -> 5 | N11: =[2]S1!P12 -> 9929832722
A12: 3059 | B12: =[3]Name!E2063 -> Aaman Kumar Depan | C12: =[2]S1!C13 -> 0 | D12: =[2]S1!D13 -> 0 | E12: =[2]S1!E13 -> 200 | F12: =[2]S1!F13 -> 0 | G12: =[2]S1!G13 -> 0 | H12: =[2]S1!H13 -> 0 | I12: =[2]S1!I13 -> 178 | J12: =[2]S1!J13 -> 0 | ... M12: =[2]S1!M13 -> 2 | N12: =[2]S1!P13 -> 9929832722
A13: 3060 | B13: =[3]Name!E2064 -> Sunita Devi Depan | C13: =[2]S1!C14 -> 1500 | D13: =[2]S1!D14 -> 0 | E13: =[2]S1!E14 -> 0 | F13: =[2]S1!F14 -> 0 | G13: =[2]S1!G14 -> 1500 | H13: =[2]S1!H14 -> 0 | I13: =[2]S1!I14 -> 240 | J13: =[2]S1!J14 -> 0 | ... M13: =[2]S1!M14 -> 5 | N13: =[2]S1!P14 -> 9929832722
A14: 3061 | B14: =[3]Name!E2065 -> Hari Om Balai | C14: =[2]S1!C15 -> 1200 | D14: =[2]S1!D15 -> 0 | E14: =[2]S1!E15 -> 200 | F14: =[2]S1!F15 -> 0 | G14: =[2]S1!G15 -> 0 | H14: =[2]S1!H15 -> 0 | I14: =[2]S1!I15 -> 120 | J14: =[2]S1!J15 -> 0 | ... M14: =[2]S1!M15 -> 4 | N14: =[2]S1!P15 -> 8000857197
A15: 3062 | B15: =[3]Name!E2066 -> Darm Pal Bunkar | C15: =[2]S1!C16 -> 0 | D15: =[2]S1!D16 -> 0 | E15: =[2]S1!E16 -> 200 | F15: =[2]S1!F16 -> 0 | G15: =[2]S1!G16 -> 0 | H15: =[2]S1!H16 -> 0 | I15: =[2]S1!I16 -> 230 | J15: =[2]S1!J16 -> 0 | ... M15: =[2]S1!M16 -> 1 | N15: =[2]S1!P16 -> 8000857197
A16: 3063 | B16: =[3]Name!E2067 -> Babu Lal Gotwal | C16: =[2]S1!C17 -> 500 | D16: =[2]S1!D17 -> 0 | E16: =[2]S1!E17 -> 200 | F16: =[2]S1!F17 -> 0 | G16: =[2]S1!G17 -> 500 | H16: =[2]S1!H17 -> 0 | I16: =[2]S1!I17 -> 580 | J16: =[2]S1!J17 -> 0 | ... M16: =[2]S1!M17 -> 5 | N16: =[2]S1!P17 -> 9928466340
... A1379: 4426 | B1379: =[3]Name!E3430 -> 0 | C1379: =[2]S1!C1380 -> 0 | D1379: =[2]S1!D1380 -> 0 | E1379: =[2]S1!E1380 -> 0 | F1379: =[2]S1!F1380 -> 0 | G1379: =[2]S1!G1380 -> 0 | H1379: =[2]S1!H1380 -> 0 | I1379: =[2]S1!I1380 -> 0 | J1379: =[2]S1!J1380 -> 0 | ... M1379: =[2]S1!M1380 -> 0 | N1379: =[2]S1!P1380 -> 0
A1380: dqy ;ksx | C1380: =SUM(C4:C1379) -> 2247172 | D1380: =SUM(D4:D788) -> 705102 | E1380: =SUM(E4:E1379) -> 495768 | F1380: =SUM(F4:F1379) -> 163467 | G1380: =SUM(G4:G1379) -> 2012196 | H1380: =SUM(H4:H1379) -> 799562 | I1380: =SUM(I4:I1379) -> 533930 | J1380: =SUM(J4:J1379) -> 7702 | K1380: =SUM(K4:K1379) -> 4012625 | L1380: =SUM(L4:L1379) -> 18864383 | N1380: =SUM(N4:N1379) -> 18718789412240
A1381: g- v/;{k | D1381: g- dSf'k;j | H1381: g- lfpo | K1381: g- ys[kkdkj

Sheet Total
E1: ='S1'!A1 -> Balai Svyam Seva Sasthan Surpura
A2: Kandelwal Software | F2: ='S1'!A2 -> 44817
A3: A/c no. | B3: Name | C3: Kist | D3: K.P. | E3: Loan | F3: L.P. | G3: Inter | H3: Other | I3: Total | J3: L.Balance | K3: Nest Lo.
A4: =IFERROR(AC!A2,"") -> 0 | B4: =VLOOKUP(A4,'S1'!A$4:B$788,2,FALSE) -> 0 | C4: =VLOOKUP(A4,'S1'!A$4:E$788,5,FALSE) -> 0 | D4: =VLOOKUP(A4,'S1'!A$4:F$788,6,FALSE) -> 0 | E4: =VLOOKUP(A4,'S1'!A$4:G$788,7,FALSE) -> 0 | F4: =VLOOKUP(A4,'S1'!A$4:H$788,8,FALSE) -> 0 | G4: =VLOOKUP(A4,'S1'!A$4:I$788,9,FALSE) -> 0 | H4: =VLOOKUP(A4,'S1'!A$4:J$788,10,FALSE) -> 0 | I4: =SUM(C4:H4) -> 0 | J4: =VLOOKUP(A4,'S1'!A$4:L$788,12,FALSE) -> 0 | K4: =VLOOKUP(A4,'S1'!A$4:C$788,3,FALSE) -> 0
A5: =IFERROR(AC!A3,"") -> 0 | B5: =VLOOKUP(A5,'S1'!A$4:B$788,2,FALSE) -> 0 | C5: =VLOOKUP(A5,'S1'!A$4:E$788,5,FALSE) -> 0 | D5: =VLOOKUP(A5,'S1'!A$4:F$788,6,FALSE) -> 0 | E5: =VLOOKUP(A5,'S1'!A$4:G$788,7,FALSE) -> 0 | F5: =VLOOKUP(A5,'S1'!A$4:H$788,8,FALSE) -> 0 | G5: =VLOOKUP(A5,'S1'!A$4:I$788,9,FALSE) -> 0 | H5: =VLOOKUP(A5,'S1'!A$4:J$788,10,FALSE) -> 0 | I5: =SUM(C5:H5) -> 0 | J5: =VLOOKUP(A5,'S1'!A$4:L$788,12,FALSE) -> 0 | K5: =VLOOKUP(A5,'S1'!A$4:C$788,3,FALSE) -> 0
A6: =IFERROR(AC!A4,"") -> 0 | B6: =VLOOKUP(A6,'S1'!A$4:B$788,2,FALSE) -> 0 | C6: =VLOOKUP(A6,'S1'!A$4:E$788,5,FALSE) -> 0 | D6: =VLOOKUP(A6,'S1'!A$4:F$788,6,FALSE) -> 0 | E6: =VLOOKUP(A6,'S1'!A$4:G$788,7,FALSE) -> 0 | F6: =VLOOKUP(A6,'S1'!A$4:H$788,8,FALSE) -> 0 | G6: =VLOOKUP(A6,'S1'!A$4:I$788,9,FALSE) -> 0 | H6: =VLOOKUP(A6,'S1'!A$4:J$788,10,FALSE) -> 0 | I6: =SUM(C6:H6) -> 0 | J6: =VLOOKUP(A6,'S1'!A$4:L$788,12,FALSE) -> 0 | K6: =VLOOKUP(A6,'S1'!A$4:C$788,3,FALSE) -> 0
A7: =IFERROR(AC!A5,"") -> 0 | B7: =VLOOKUP(A7,'S1'!A$4:B$788,2,FALSE) -> 0 | C7: =VLOOKUP(A7,'S1'!A$4:E$788,5,FALSE) -> 0 | D7: =VLOOKUP(A7,'S1'!A$4:F$788,6,FALSE) -> 0 | E7: =VLOOKUP(A7,'S1'!A$4:G$788,7,FALSE) -> 0 | F7: =VLOOKUP(A7,'S1'!A$4:H$788,8,FALSE) -> 0 | G7: =VLOOKUP(A7,'S1'!A$4:I$788,9,FALSE) -> 0 | H7: =VLOOKUP(A7,'S1'!A$4:J$788,10,FALSE) -> 0 | I7: =SUM(C7:H7) -> 0 | J7: =VLOOKUP(A7,'S1'!A$4:L$788,12,FALSE) -> 0 | K7: =VLOOKUP(A7,'S1'!A$4:C$788,3,FALSE) -> 0
A8: =IFERROR(AC!A6,"") -> 0 | B8: =VLOOKUP(A8,'S1'!A$4:B$788,2,FALSE) -> 0 | C8: =VLOOKUP(A8,'S1'!A$4:E$788,5,FALSE) -> 0 | D8: =VLOOKUP(A8,'S1'!A$4:F$788,6,FALSE) -> 0 | E8: =VLOOKUP(A8,'S1'!A$4:G$788,7,FALSE) -> 0 | F8: =VLOOKUP(A8,'S1'!A$4:H$788,8,FALSE) -> 0 | G8: =VLOOKUP(A8,'S1'!A$4:I$788,9,FALSE) -> 0 | H8: =VLOOKUP(A8,'S1'!A$4:J$788,10,FALSE) -> 0 | I8: =SUM(C8:H8) -> 0 | J8: =VLOOKUP(A8,'S1'!A$4:L$788,12,FALSE) -> 0 | K8: =VLOOKUP(A8,'S1'!A$4:C$788,3,FALSE) -> 0
A9: =IFERROR(AC!A7,"") -> 0 | B9: =VLOOKUP(A9,'S1'!A$4:B$788,2,FALSE) -> 0 | C9: =VLOOKUP(A9,'S1'!A$4:E$788,5,FALSE) -> 0 | D9: =VLOOKUP(A9,'S1'!A$4:F$788,6,FALSE) -> 0 | E9: =VLOOKUP(A9,'S1'!A$4:G$788,7,FALSE) -> 0 | F9: =VLOOKUP(A9,'S1'!A$4:H$788,8,FALSE) -> 0 | G9: =VLOOKUP(A9,'S1'!A$4:I$788,9,FALSE) -> 0 | H9: =VLOOKUP(A9,'S1'!A$4:J$788,10,FALSE) -> 0 | I9: =SUM(C9:H9) -> 0 | J9: =VLOOKUP(A9,'S1'!A$4:L$788,12,FALSE) -> 0 | K9: =VLOOKUP(A9,'S1'!A$4:C$788,3,FALSE) -> 0
A10: =IFERROR(AC!A8,"") -> 0 | B10: =VLOOKUP(A10,'S1'!A$4:B$788,2,FALSE) -> 0 | C10: =VLOOKUP(A10,'S1'!A$4:E$788,5,FALSE) -> 0 | D10: =VLOOKUP(A10,'S1'!A$4:F$788,6,FALSE) -> 0 | E10: =VLOOKUP(A10,'S1'!A$4:G$788,7,FALSE) -> 0 | F10: =VLOOKUP(A10,'S1'!A$4:H$788,8,FALSE) -> 0 | G10: =VLOOKUP(A10,'S1'!A$4:I$788,9,FALSE) -> 0 | H10: =VLOOKUP(A10,'S1'!A$4:J$788,10,FALSE) -> 0 | I10: =SUM(C10:H10) -> 0 | J10: =VLOOKUP(A10,'S1'!A$4:L$788,12,FALSE) -> 0 | K10: =VLOOKUP(A10,'S1'!A$4:C$788,3,FALSE) -> 0
A11: =IFERROR(AC!A9,"") -> 0 | B11: =VLOOKUP(A11,'S1'!A$4:B$788,2,FALSE) -> 0 | C11: =VLOOKUP(A11,'S1'!A$4:E$788,5,FALSE) -> 0 | D11: =VLOOKUP(A11,'S1'!A$4:F$788,6,FALSE) -> 0 | E11: =VLOOKUP(A11,'S1'!A$4:G$788,7,FALSE) -> 0 | F11: =VLOOKUP(A11,'S1'!A$4:H$788,8,FALSE) -> 0 | G11: =VLOOKUP(A11,'S1'!A$4:I$788,9,FALSE) -> 0 | H11: =VLOOKUP(A11,'S1'!A$4:J$788,10,FALSE) -> 0 | I11: =SUM(C11:H11) -> 0 | J11: =VLOOKUP(A11,'S1'!A$4:L$788,12,FALSE) -> 0 | K11: =VLOOKUP(A11,'S1'!A$4:C$788,3,FALSE) -> 0
A12: =IFERROR(AC!A10,"") -> 0 | B12: =VLOOKUP(A12,'S1'!A$4:B$788,2,FALSE) -> 0 | C12: =VLOOKUP(A12,'S1'!A$4:E$788,5,FALSE) -> 0 | D12: =VLOOKUP(A12,'S1'!A$4:F$788,6,FALSE) -> 0 | E12: =VLOOKUP(A12,'S1'!A$4:G$788,7,FALSE) -> 0 | F12: =VLOOKUP(A12,'S1'!A$4:H$788,8,FALSE) -> 0 | G12: =VLOOKUP(A12,'S1'!A$4:I$788,9,FALSE) -> 0 | H12: =VLOOKUP(A12,'S1'!A$4:J$788,10,FALSE) -> 0 | I12: =SUM(C12:H12) -> 0 | J12: =VLOOKUP(A12,'S1'!A$4:L$788,12,FALSE) -> 0 | K12: =VLOOKUP(A12,'S1'!A$4:C$788,3,FALSE) -> 0
A13: =IFERROR(AC!A11,"") -> 0 | B13: =VLOOKUP(A13,'S1'!A$4:B$788,2,FALSE) -> 0 | C13: =VLOOKUP(A13,'S1'!A$4:E$788,5,FALSE) -> 0 | D13: =VLOOKUP(A13,'S1'!A$4:F$788,6,FALSE) -> 0 | E13: =VLOOKUP(A13,'S1'!A$4:G$788,7,FALSE) -> 0 | F13: =VLOOKUP(A13,'S1'!A$4:H$788,8,FALSE) -> 0 | G13: =VLOOKUP(A13,'S1'!A$4:I$788,9,FALSE) -> 0 | H13: =VLOOKUP(A13,'S1'!A$4:J$788,10,FALSE) -> 0 | I13: =SUM(C13:H13) -> 0 | J13: =VLOOKUP(A13,'S1'!A$4:L$788,12,FALSE) -> 0 | K13: =VLOOKUP(A13,'S1'!A$4:C$788,3,FALSE) -> 0
A14: Total | C14: =SUM(C4:C13) -> 0 | D14: =SUM(D4:D13) -> 0 | E14: =SUM(E4:E13) -> 0 | F14: =SUM(F4:F13) -> 0 | G14: =SUM(G4:G13) -> 0 | H14: =SUM(H4:H13) -> 0 | I14: =SUM(I4:I13) -> 0 | J14: =SUM(J4:J13) -> 0 | K14: =SUM(K4:K13) -> 0

Sheet AC
A1: A/c no.

Sheet Sheet1
A1: import streamlit as st | J1: import streamlit as st | T1: import streamlit as st | AC1: import streamlit as st
A2: import pandas as pd | J2: import pandas as pd | T2: import pandas as pd | AC2: import pandas as pd
A4: st.set_page_config(layout="wide") | J4: st.set_page_config(layout="wide") | T4: st.set_page_config(layout="wide") | AC4: st.set_page_config(layout="wide")
A5: st.markdown("Balai Svyam Seva Sasthan Surpura") # ← Yahan se 📊 hata diya | J5: st.markdown("Balai Svyam Seva Sasthan Surpura") # ← Yahan se 📊 hata diya | T5: st.markdown("Balai Svyam Seva Sasthan Surpura") # ← Yahan se 📊 hata diya | AC5: st.markdown("Balai Svyam Seva Sasthan Surpura") # ← Yahan se 📊 hata diya
A7: def load_data(): | J7: def load_data(): | T7: def load_data(): | AC7: def load_data():
A8: # encoding fix aur khali rows hatana | J8: # --- NYA CODE: A2 cell se date nikalne ke liye --- | T8: # --- A2 cell se date nikalne ke liye --- | AC8: # --- A2 cell se date nikalne ke liye ---
A9: df = pd.read_csv(r"e:\python\LTM.csv", header=2, encoding='latin-1').dropna(how='all') | J9: # Header=None rakhkar pehle 2 rows padhenge taaki A2 cell ka data mil sake | T9: raw_df = pd.read_csv(r"e:\python\LTM.csv", header=None, nrows=2, encoding='latin-1') | AC9: raw_df = pd.read_csv(r"e:\python\LTM.csv", header=None, nrows=2, encoding='latin-1')
A10: df.columns = df.columns.str.strip() | J10: raw_df = pd.read_csv(r"e:\python\LTM.csv", header=None, nrows=2, encoding='latin-1') | T10: try: | AC10: try:
J11: try: | T11: # Excel ka A2 cell = Row Index 1 (2nd row) aur Column Index 0 (A column) | AC11: # Excel ka A2 cell = Row Index 1 (2nd row) aur Column Index 0 (A column)
A12: if 'phone' in df.columns: | J12: # Excel ka A2 cell = Row Index 1 (2nd row) aur Column Index 0 (A column) | T12: extracted_date = raw_df.iloc[1, 0] | AC12: extracted_date = raw_df.iloc[1, 0]
A13: df['phone'] = df['phone'].astype(str).str.replace(r'\.0$', '', regex=True).str.strip() | J13: extracted_date = raw_df.iloc[1, 0] | T13: except Exception: | AC13: except Exception:
J14: except Exception: | T14: extracted_date = "" | AC14: extracted_date = ""
A15: # Sabhi 'None' ya 'NaN' values ko khali string se badal dena | J15: extracted_date = ""
A16: df = df.fillna('') | J16: # ------------------------------------------------ | T16: # Data loading (Header=2 se) | AC16: # Data loading (Header=2 se)
A17: return df | T17: df = pd.read_csv(r"e:\python\LTM.csv", header=2, encoding='latin-1').dropna(how='all') | AC17: df = pd.read_csv(r"e:\python\LTM.csv", header=2, encoding='latin-1').dropna(how='all')
J18: # Encoding fix aur khali rows hatana (Header=2 se data start ho raha hai) | T18: df.columns = df.columns.str.strip() | AC18: df.columns = df.columns.str.strip()
A19: # FUNCTION TO HIGHLIGHT TOTAL ROW IN RED | J19: df = pd.read_csv(r"e:\python\LTM.csv", header=2, encoding='latin-1').dropna(how='all')
A20: def highlight_total_row(row): | J20: df.columns = df.columns.str.strip() | T20: # Phone number ko normal string rakhna taaki search sahi ho | AC20: # Phone number ko normal string rakhna taaki search sahi ho
A21: if row.get('Name') == 'TOTAL': | T21: if 'phone' in df.columns: | AC21: if 'phone' in df.columns:
A22: return ['background-color: #ffcccc; color: #cc0000; font-weight: bold'] * len(row) | J22: if 'phone' in df.columns: | T22: df['phone'] = df['phone'].astype(str).str.replace(r'\.0$', '', regex=True).str.strip() | AC22: df['phone'] = df['phone'].astype(str).str.replace(r'\.0$', '', regex=True).str.strip()
A23: else: | J23: df['phone'] = df['phone'].astype(str).str.replace(r'\.0$', '', regex=True).str.strip()
A24: return [''] * len(row) | T24: # Baaki columns ke andar ke values ko number me badalna taaki total sahi nikle | AC24: # Baaki columns ke andar ke values ko number me badalna taaki total sahi nikle
J25: # Sabhi 'None' ya 'NaN' values ko khali string se badal dena | T25: num_cols = ['Nest Lo.', 'Discount', 'Kist', 'K.P.', 'Loan', 'L.P.', 'Inter', 'Other', 'Total', 'L.Balance'] | AC25: num_cols = ['Nest Lo.', 'Discount', 'Kist', 'K.P.', 'Loan', 'L.P.', 'Inter', 'Other', 'Total', 'L.Balance']
A26: try: | J26: df = df.fillna('') | T26: for col in df.columns: | AC26: for col in df.columns:
A27: df = load_data() | T27: if col in num_cols: | AC27: if col in num_cols:
J28: # Dataframe aur Date dono ek sath return honge | T28: df[col] = df[col].astype(str).str.replace(',', '').str.strip() | AC28: df[col] = df[col].astype(str).str.replace(',', '').str.strip()
A29: val = st.text_input("Mobile Number Enter Karein:") | J29: return df, extracted_date | T29: df[col] = pd.to_numeric(df[col], errors='coerce') | AC29: df[col] = pd.to_numeric(df[col], errors='coerce')
A31: if val: | J31: # FUNCTION TO HIGHLIGHT TOTAL ROW IN RED | T31: return df, extracted_date | AC31: return df, extracted_date
A32: if 'phone' not in df.columns: | J32: def highlight_total_row(row):
A33: st.error("Phone column nahi mila!") | J33: if row.get('Name') == 'TOTAL': | T33: # FUNCTION TO HIGHLIGHT TOTAL ROW IN RED | AC33: # FUNCTION TO HIGHLIGHT TOTAL ROW IN RED
A34: st.write("Available columns:", df.columns.tolist()) | J34: return ['background-color: #ffcccc; color: #cc0000; font-weight: bold'] * len(row) | T34: def highlight_total_row(row): | AC34: def highlight_total_row(row):
A35: else: | J35: else: | T35: if row.get('Name') == 'TOTAL': | AC35: if row.get('Name') == 'TOTAL':
A36: res = df[df['phone'].astype(str).str.contains(str(val), na=False, regex=False)].copy() | J36: return [''] * len(row) | T36: return ['background-color: #ffcccc; color: #cc0000; font-weight: bold'] * len(row) | AC36: return ['background-color: #ffcccc; color: #cc0000; font-weight: bold'] * len(row)
T37: else: | AC37: else:
A38: if not res.empty: | J38: try: | T38: return [''] * len(row) | AC38: return [''] * len(row)
A39: num_cols = ['Nest Lo.', 'Discount', 'Kist', 'K.P.', 'Loan', 'L.P.', 'Inter', 'Other', 'Total', 'L.Balance'] | J39: # load_data se dono cheezein le rahe hain
A40: existing_num_cols = [col for col in num_cols if col in df.columns] | J40: df, file_date = load_data() | T40: try: | AC40: try:
T41: df, file_date = load_data() | AC41: df, file_date = load_data()
A42: sums = {} | J42: # --- NYA CODE: Input Box ke upar right side me Date lagane ke liye ---
A43: for col in res.columns: | J43: col1, col2 = st.columns([3, 1]) # Screen ko 75% aur 25% ke ratio me baanta | T43: # --- INPUT TEXT KE BILKUL BARABAR RIGHT MEIN DATE --- | AC43: # --- INPUT TEXT KE BILKUL BARABAR RIGHT MEIN DATE ---
...
